Workbook

Sheet 分区表
A1: AreaID | B1: AreaName | C1: ProvinceID
A2: 1 | B2: 徐宿淮 | C2: JS
A3: 2 | B3: 连盐通 | C3: JS
A4: 3 | B4: 扬泰 | C4: JS
A5: 4 | B5: 宁镇常 | C5: JS
A6: 5 | B6: 锡苏 | C6: JS

Sheet 煤电
A1: UnitKey | B1: ID | C1: NAME | D1: SUBSTR(C.ID，12) | E1: PLANT_ID | F1: CAP | G1: MIN_POWER_GEN | H1: MIN_DOWN_TIME | I1: MIN_UP_TIME | J1: RAMP_LIMIT_UP | K1: RAMP_LIMIT_DOWN | L1: COST_A | M1: COST_B | N1: COST_C | O1: COST_START_UP | P1: COST_SHUT_DOWN | Q1: MIN_POWER_CHARGE | R1: MAX_POWER_CHARGE | S1: GEN_AFFI_FACTOR | T1: CHAEGE_AFFI_FACTOR | U1: INIT_STATUS | V1: INIT_POWER | W1: FOM_COST_PERIOD | X1: INIT_HOURS | Y1: START_RAMP | Z1: STOP_RAMP | AA1: SO2_FACTOR | AB1: NOX_FACTOR | AC1: DUST_FACTOR | AD1: DataStatus
A2: TH_0001 | B2: 930632000000000000 | C2: 苏华金_127.0机_JM | D2: 1 | E2: 93043200000000 | F2: 1000 | G2: 300 | H2: 168 | I2: 72 | J2: 1200 | K2: 1200 | L2: 3e-06 | M2: 0.008 | N2: 0.8 | O2: 30 | P2: 30 | Q2: 0 | R2: 0 | S2: 0 | T2: 0 | U2: 1 | V2: 300 | W2: 8.4 | X2: 168 | Y2: 300 | Z2: 1000 | AA2: 0.0001 | AB2: 0.00015 | AC2: 1.5e-05 | AD2: 原值保留；补值为算例假设，见字段说明
A3: TH_0002 | B3: 930632000000000000 | C3: 苏华金_227.0机_JM | D3: 1 | E3: 93043200000000 | F3: 1000 | G3: 300 | H3: 168 | I3: 72 | J3: 1200 | K3: 1200 | L3: 3e-06 | M3: 0.008 | N3: 0.8 | O3: 30 | P3: 30 | Q3: 0 | R3: 0 | S3: 0 | T3: 0 | U3: 1 | V3: 300 | W3: 8.4 | X3: 168 | Y3: 300 | Z3: 1000 | AA3: 0.0001 | AB3: 0.00015 | AC3: 1.5e-05 | AD3: 原值保留；补值为算例假设，见字段说明
A4: TH_0003 | B4: 930632000000000000 | C4: 苏大唐_120.0机_Jm | D4: 1 | E4: 93043200000000 | F4: 660 | G4: 198 | H4: 168 | I4: 72 | J4: 792 | K4: 792 | L4: 3e-06 | M4: 0.008 | N4: 0.8 | O4: 30 | P4: 30 | Q4: 0 | R4: 0 | S4: 0 | T4: 0 | U4: 1 | V4: 198 | W4: 8.4 | X4: 168 | Y4: 198 | Z4: 660 | AA4: 0.0001 | AB4: 0.00015 | AC4: 1.5e-05 | AD4: 原值保留；补值为算例假设，见字段说明
A5: TH_0004 | B5: 930632000000000000 | C5: 苏大唐_220.0机_Jm | D5: 1 | E5: 93043200000000 | F5: 660 | G5: 198 | H5: 168 | I5: 72 | J5: 792 | K5: 792 | L5: 3e-06 | M5: 0.008 | N5: 0.8 | O5: 30 | P5: 30 | Q5: 0 | R5: 0 | S5: 0 | T5: 0 | U5: 1 | V5: 198 | W5: 8.4 | X5: 168 | Y5: 198 | Z5: 660 | AA5: 0.0001 | AB5: 0.00015 | AC5: 1.5e-05 | AD5: 原值保留；补值为算例假设，见字段说明
A6: TH_0005 | B6: 930632000000000000 | C6: 苏南热_122.0机_Jm | D6: 1 | E6: 93043200000000 | F6: 600 | G6: 180 | H6: 168 | I6: 72 | J6: 720 | K6: 720 | L6: 5e-06 | M6: 0.01 | N6: 0.5 | O6: 8 | P6: 8 | Q6: 0 | R6: 0 | S6: 0 | T6: 0 | U6: 1 | V6: 180 | W6: 8.4 | X6: 168 | Y6: 180 | Z6: 600 | AA6: 0.0001 | AB6: 0.00015 | AC6: 1.5e-05 | AD6: 原值保留；补值为算例假设，见字段说明
A7: TH_0006 | B7: 930632000000000000 | C7: 苏南热_222.0机_Jm | D7: 1 | E7: 93043200000000 | F7: 600 | G7: 180 | H7: 168 | I7: 72 | J7: 720 | K7: 720 | L7: 5e-06 | M7: 0.01 | N7: 0.5 | O7: 8 | P7: 8 | Q7: 0 | R7: 0 | S7: 0 | T7: 0 | U7: 1 | V7: 180 | W7: 8.4 | X7: 168 | Y7: 180 | Z7: 600 | AA7: 0.0001 | AB7: 0.00015 | AC7: 1.5e-05 | AD7: 原值保留；补值为算例假设，见字段说明
A8: TH_0007 | B8: 930632000000000000 | C8: 南京非统调 | D8: 1 | E8: 93043200000000 | F8: 120 | G8: 72 | H8: 168 | I8: 72 | J8: 144 | K8: 144 | L8: 5e-06 | M8: 0.01 | N8: 0.5 | O8: 8 | P8: 8 | Q8: 0 | R8: 0 | S8: 0 | T8: 0 | U8: 1 | V8: 72 | W8: 8.4 | X8: 168 | Y8: 72 | Z8: 120 | AA8: 0.0001 | AB8: 0.00015 | AC8: 1.5e-05 | AD8: 原值保留；补值为算例假设，见字段说明
A9: TH_0008 | B9: 930632000000000000 | C9: 苏华润_320.0机_Jm | D9: 1 | E9: 93043200000000 | F9: 330 | G9: 99 | H9: 168 | I9: 72 | J9: 396 | K9: 396 | L9: 5e-06 | M9: 0.01 | N9: 0.5 | O9: 8 | P9: 8 | Q9: 0 | R9: 0 | S9: 0 | T9: 0 | U9: 1 | V9: 99 | W9: 8.4 | X9: 168 | Y9: 99 | Z9: 330 | AA9: 0.0001 | AB9: 0.00015 | AC9: 1.5e-05 | AD9: 原值保留；补值为算例假设，见字段说明
A10: TH_0009 | B10: 930632000000000000 | C10: 苏华润_420.0机_Jm | D10: 1 | E10: 93043200000000 | F10: 330 | G10: 99 | H10: 168 | I10: 72 | J10: 396 | K10: 396 | L10: 5e-06 | M10: 0.01 | N10: 0.5 | O10: 8 | P10: 8 | Q10: 0 | R10: 0 | S10: 0 | T10: 0 | U10: 1 | V10: 99 | W10: 8.4 | X10: 168 | Y10: 99 | Z10: 330 | AA10: 0.0001 | AB10: 0.00015 | AC10: 1.5e-05 | AD10: 原值保留；补值为算例假设，见字段说明
A11: TH_0010 | B11: 930632000000000000 | C11: 苏华京_120.0机_Jm | D11: 1 | E11: 93043200000000 | F11: 320 | G11: 96 | H11: 168 | I11: 72 | J11: 384 | K11: 384 | L11: 5e-06 | M11: 0.01 | N11: 0.5 | O11: 8 | P11: 8 | Q11: 0 | R11: 0 | S11: 0 | T11: 0 | U11: 1 | V11: 96 | W11: 8.4 | X11: 168 | Y11: 96 | Z11: 320 | AA11: 0.0001 | AB11: 0.00015 | AC11: 1.5e-05 | AD11: 原值保留；补值为算例假设，见字段说明
A12: TH_0011 | B12: 930632000000000000 | C12: 苏华京_220.0机_Jm | D12: 1 | E12: 93043200000000 | F12: 320 | G12: 96 | H12: 168 | I12: 72 | J12: 384 | K12: 384 | L12: 5e-06 | M12: 0.01 | N12: 0.5 | O12: 8 | P12: 8 | Q12: 0 | R12: 0 | S12: 0 | T12: 0 | U12: 1 | V12: 96 | W12: 8.4 | X12: 168 | Y12: 96 | Z12: 320 | AA12: 0.0001 | AB12: 0.00015 | AC12: 1.5e-05 | AD12: 原值保留；补值为算例假设，见字段说明
A13: TH_0012 | B13: 930632000000000000 | C13: 苏宁热_420.0机_Jm | D13: 1 | E13: 93043200000000 | F13: 300 | G13: 90 | H13: 168 | I13: 72 | J13: 360 | K13: 360 | L13: 5e-06 | M13: 0.01 | N13: 0.5 | O13: 8 | P13: 8 | Q13: 0 | R13: 0 | S13: 0 | T13: 0 | U13: 1 | V13: 90 | W13: 8.4 | X13: 168 | Y13: 90 | Z13: 300 | AA13: 0.0001 | AB13: 0.00015 | AC13: 1.5e-05 | AD13: 原值保留；补值为算例假设，见字段说明
... A173: TH_0172 | B173: 930632000000000000 | C173: 苏中自G513.8机_Jm | D173: 5 | E173: 93043200000000 | F173: 100 | G173: 45 | H173: 168 | I173: 72 | J173: 120 | K173: 120 | L173: 8e-06 | M173: 0.012 | N173: 0.3 | O173: 3 | P173: 3 | Q173: 0 | R173: 0 | S173: 0 | T173: 0 | U173: 1 | V173: 45 | W173: 8.4 | X173: 168 | Y173: 45 | Z173: 100 | AA173: 0.0001 | AB173: 0.00015 | AC173: 1.5e-05 | AD173: 原值保留；补值为算例假设，见字段说明

Sheet 气电
A1: UnitKey | B1: ID | C1: NAME | D1: SUBSTR(C.ID，12) | E1: PLANT_ID | F1: CAP | G1: MIN_POWER_GEN | H1: MIN_DOWN_TIME | I1: MIN_UP_TIME | J1: RAMP_LIMIT_UP | K1: RAMP_LIMIT_DOWN | L1: COST_A | M1: COST_B | N1: COST_C | O1: COST_START_UP | P1: COST_SHUT_DOWN | Q1: MIN_POWER_CHARGE | R1: MAX_POWER_CHARGE | S1: GEN_AFFI_FACTOR | T1: CHAEGE_AFFI_FACTOR | U1: INIT_STATUS | V1: INIT_POWER | W1: FOM_COST_PERIOD | X1: START_RAMP | Y1: STOP_RAMP | Z1: CO2_FACTOR | AA1: GEN_COST | AB1: DataStatus | AC1: INIT_HOURS
A2: GAS_0001 | B2: 930632000000000000 | C2: 苏协鑫_410.5机_Jr | D2: 1 | E2: 93043200000000 | F2: 60 | G2: 46.8 | H2: 168 | I2: 96 | J2: 72 | K2: 72 | L2: 8e-06 | M2: 0.012 | N2: 0.3 | O2: 3 | P2: 3 | Q2: 0 | R2: 0 | S2: 0 | T2: 0 | U2: 0 | V2: 0 | W2: 7.4 | X2: 60 | Y2: 60 | Z2: 0.40392 | AA2: 0.04 | AB2: 原值保留；补值为算例假设，见字段说明 | AC2: 168
A3: GAS_0002 | B3: 930632000000000000 | C3: 苏协鑫_313.8机_Jr | D3: 1 | E3: 93043200000000 | F3: 120 | G3: 93.6 | H3: 168 | I3: 96 | J3: 144 | K3: 144 | L3: 8e-06 | M3: 0.012 | N3: 0.3 | O3: 3 | P3: 3 | Q3: 0 | R3: 0 | S3: 0 | T3: 0 | U3: 0 | V3: 0 | W3: 7.4 | X3: 120 | Y3: 120 | Z3: 0.40392 | AA3: 0.04 | AB3: 原值保留；补值为算例假设，见字段说明 | AC3: 168
A4: GAS_0003 | B4: 930632000000000000 | C4: 苏协鑫_210.5机_Jr | D4: 1 | E4: 93043200000000 | F4: 60 | G4: 46.8 | H4: 168 | I4: 96 | J4: 72 | K4: 72 | L4: 8e-06 | M4: 0.012 | N4: 0.3 | O4: 3 | P4: 3 | Q4: 0 | R4: 0 | S4: 0 | T4: 0 | U4: 0 | V4: 0 | W4: 7.4 | X4: 60 | Y4: 60 | Z4: 0.40392 | AA4: 0.04 | AB4: 原值保留；补值为算例假设，见字段说明 | AC4: 168
A5: GAS_0004 | B5: 930632000000000000 | C5: 苏协鑫_113.8机_Jr | D5: 1 | E5: 93043200000000 | F5: 120 | G5: 93.6 | H5: 168 | I5: 96 | J5: 144 | K5: 144 | L5: 8e-06 | M5: 0.012 | N5: 0.3 | O5: 3 | P5: 3 | Q5: 0 | R5: 0 | S5: 0 | T5: 0 | U5: 0 | V5: 0 | W5: 7.4 | X5: 120 | Y5: 120 | Z5: 0.40392 | AA5: 0.04 | AB5: 原值保留；补值为算例假设，见字段说明 | AC5: 168
A6: GAS_0005 | B6: 930632000000000000 | C6: 苏协燃G410.5机_Jr | D6: 1 | E6: 93043200000000 | F6: 120 | G6: 93.6 | H6: 168 | I6: 96 | J6: 144 | K6: 144 | L6: 8e-06 | M6: 0.012 | N6: 0.3 | O6: 3 | P6: 3 | Q6: 0 | R6: 0 | S6: 0 | T6: 0 | U6: 0 | V6: 0 | W6: 7.4 | X6: 120 | Y6: 120 | Z6: 0.40392 | AA6: 0.04 | AB6: 原值保留；补值为算例假设，见字段说明 | AC6: 168
A7: GAS_0006 | B7: 930632000000000000 | C7: 苏协燃G310.5机_Jr | D7: 1 | E7: 93043200000000 | F7: 120 | G7: 93.6 | H7: 168 | I7: 96 | J7: 144 | K7: 144 | L7: 8e-06 | M7: 0.012 | N7: 0.3 | O7: 3 | P7: 3 | Q7: 0 | R7: 0 | S7: 0 | T7: 0 | U7: 0 | V7: 0 | W7: 7.4 | X7: 120 | Y7: 120 | Z7: 0.40392 | AA7: 0.04 | AB7: 原值保留；补值为算例假设，见字段说明 | AC7: 168
A8: GAS_0007 | B8: 930632000000000000 | C8: 苏陵燃_315.7机_Jr | D8: 1 | E8: 93043200000000 | F8: 180 | G8: 140.4 | H8: 168 | I8: 96 | J8: 216 | K8: 216 | L8: 8e-06 | M8: 0.012 | N8: 0.3 | O8: 3 | P8: 3 | Q8: 0 | R8: 0 | S8: 0 | T8: 0 | U8: 0 | V8: 0 | W8: 7.4 | X8: 180 | Y8: 180 | Z8: 0.40392 | AA8: 0.04 | AB8: 原值保留；补值为算例假设，见字段说明 | AC8: 168
A9: GAS_0008 | B9: 930632000000000000 | C9: 苏溧燃G410.5机_Jr | D9: 1 | E9: 93043200000000 | F9: 120 | G9: 93.6 | H9: 168 | I9: 96 | J9: 144 | K9: 144 | L9: 8e-06 | M9: 0.012 | N9: 0.3 | O9: 3 | P9: 3 | Q9: 0 | R9: 0 | S9: 0 | T9: 0 | U9: 0 | V9: 0 | W9: 7.4 | X9: 120 | Y9: 120 | Z9: 0.40392 | AA9: 0.04 | AB9: 原值保留；补值为算例假设，见字段说明 | AC9: 168
A10: GAS_0009 | B10: 930632000000000000 | C10: 苏溧燃G310.5机_Jr | D10: 1 | E10: 93043200000000 | F10: 120 | G10: 93.6 | H10: 168 | I10: 96 | J10: 144 | K10: 144 | L10: 8e-06 | M10: 0.012 | N10: 0.3 | O10: 3 | P10: 3 | Q10: 0 | R10: 0 | S10: 0 | T10: 0 | U10: 0 | V10: 0 | W10: 7.4 | X10: 120 | Y10: 120 | Z10: 0.40392 | AA10: 0.04 | AB10: 原值保留；补值为算例假设，见字段说明 | AC10: 168
A11: GAS_0010 | B11: 930632000000000000 | C11: 苏唐燃G120.0机_Jr | D11: 1 | E11: 93043200000000 | F11: 655 | G11: 491.25 | H11: 8 | I11: 8 | J11: 786 | K11: 786 | L11: 3e-06 | M11: 0.008 | N11: 0.8 | O11: 30 | P11: 30 | Q11: -655 | R11: 655 | S11: 0 | T11: 0 | U11: 0 | V11: 0 | W11: 7.4 | X11: 655 | Y11: 655 | Z11: 0.40392 | AA11: 0.04 | AB11: 原值保留；补值为算例假设，见字段说明 | AC11: 8
A12: GAS_0011 | B12: 930632000000000000 | C12: 苏唐燃G220.0机_Jr | D12: 1 | E12: 93043200000000 | F12: 655 | G12: 491.25 | H12: 8 | I12: 8 | J12: 786 | K12: 786 | L12: 3e-06 | M12: 0.008 | N12: 0.8 | O12: 30 | P12: 30 | Q12: -655 | R12: 655 | S12: 0 | T12: 0 | U12: 0 | V12: 0 | W12: 7.4 | X12: 655 | Y12: 655 | Z12: 0.40392 | AA12: 0.04 | AB12: 原值保留；补值为算例假设，见字段说明 | AC12: 8
A13: GAS_0012 | B13: 930632000000000000 | C13: 苏陵燃_127.0机_Jr | D13: 1 | E13: 93043200000000 | F13: 390 | G13: 292.5 | H13: 8 | I13: 8 | J13: 468 | K13: 468 | L13: 5e-06 | M13: 0.01 | N13: 0.5 | O13: 8 | P13: 8 | Q13: -390 | R13: 390 | S13: 0 | T13: 0 | U13: 0 | V13: 0 | W13: 7.4 | X13: 390 | Y13: 390 | Z13: 0.40392 | AA13: 0.04 | AB13: 原值保留；补值为算例假设，见字段说明 | AC13: 8
... A125: GAS_0124 | B125: 930632000000000000 | C125: 苏华燃G224.0机_Jr | D125: 5 | E125: 93043200000000 | F125: 745 | G125: 558.75 | H125: 8 | I125: 8 | J125: 894 | K125: 894 | L125: 3e-06 | M125: 0.008 | N125: 0.8 | O125: 30 | P125: 30 | Q125: -745 | R125: 745 | S125: 0 | T125: 0 | U125: 0 | V125: 0 | W125: 7.4 | X125: 745 | Y125: 745 | Z125: 0.40392 | AA125: 0.04 | AB125: 原值保留；补值为算例假设，见字段说明 | AC125: 8

Sheet 抽水蓄能
A1: UnitKey | B1: ID | C1: NAME | D1: SUBSTR(C.ID，12) | E1: PLANT_ID | F1: CAP | G1: MIN_POWER_GEN | H1: MIN_DOWN_TIME | I1: MIN_UP_TIME | J1: RAMP_LIMIT_UP | K1: RAMP_LIMIT_DOWN | L1: COST_A | M1: COST_B | N1: COST_C | O1: COST_START_UP | P1: COST_SHUT_DOWN | Q1: MIN_POWER_CHARGE | R1: MAX_POWER_CHARGE | S1: GEN_AFFI_FACTOR | T1: CHAEGE_AFFI_FACTOR | U1: PUMP_MIN_MW | V1: ENERGY_MWH | W1: SOC_MIN | X1: SOC_MAX | Y1: SOC_INITIAL | Z1: FOM_COST_PERIOD | AA1: DataStatus
A2: PS_0001 | B2: 930632000000000000 | C2: 苏句抽G115.8机_JD | D2: 1 | E2: 93043200000000 | F2: 200 | G2: -200 | H2: 0 | I2: 0 | J2: 240 | K2: 240 | L2: 0 | M2: 0 | N2: 0 | O2: 1 | P2: 1 | Q2: -200 | R2: 200 | S2: 0.8 | T2: 0.8 | U2: 200 | V2: 1875 | W2: 0.1 | X2: 0.9 | Y2: 0.5 | Z2: 9 | AA2: 原值保留；补值为算例假设，见字段说明
A3: PS_0002 | B3: 930632000000000000 | C3: 苏句抽G215.8机_JD | D3: 1 | E3: 93043200000000 | F3: 200 | G3: -200 | H3: 0 | I3: 0 | J3: 240 | K3: 240 | L3: 0 | M3: 0 | N3: 0 | O3: 1 | P3: 1 | Q3: -200 | R3: 200 | S3: 0.8 | T3: 0.8 | U3: 200 | V3: 1875 | W3: 0.1 | X3: 0.9 | Y3: 0.5 | Z3: 9 | AA3: 原值保留；补值为算例假设，见字段说明
A4: PS_0003 | B4: 930632000000000000 | C4: 苏句抽G315.8机_JD | D4: 1 | E4: 93043200000000 | F4: 200 | G4: -200 | H4: 0 | I4: 0 | J4: 240 | K4: 240 | L4: 0 | M4: 0 | N4: 0 | O4: 1 | P4: 1 | Q4: -200 | R4: 200 | S4: 0.8 | T4: 0.8 | U4: 200 | V4: 1875 | W4: 0.1 | X4: 0.9 | Y4: 0.5 | Z4: 9 | AA4: 原值保留；补值为算例假设，见字段说明
A5: PS_0004 | B5: 930632000000000000 | C5: 苏句抽G415.8机_JD | D5: 1 | E5: 93043200000000 | F5: 200 | G5: -200 | H5: 0 | I5: 0 | J5: 240 | K5: 240 | L5: 0 | M5: 0 | N5: 0 | O5: 1 | P5: 1 | Q5: -200 | R5: 200 | S5: 0.8 | T5: 0.8 | U5: 200 | V5: 1875 | W5: 0.1 | X5: 0.9 | Y5: 0.5 | Z5: 9 | AA5: 原值保留；补值为算例假设，见字段说明
A6: PS_0005 | B6: 930632000000000000 | C6: 苏句抽G515.8机_JD | D6: 1 | E6: 93043200000000 | F6: 200 | G6: -200 | H6: 0 | I6: 0 | J6: 240 | K6: 240 | L6: 0 | M6: 0 | N6: 0 | O6: 1 | P6: 1 | Q6: -200 | R6: 200 | S6: 0.8 | T6: 0.8 | U6: 200 | V6: 1875 | W6: 0.1 | X6: 0.9 | Y6: 0.5 | Z6: 9 | AA6: 原值保留；补值为算例假设，见字段说明
A7: PS_0006 | B7: 930632000000000000 | C7: 苏句抽G615.8机_JD | D7: 1 | E7: 93043200000000 | F7: 200 | G7: -200 | H7: 0 | I7: 0 | J7: 240 | K7: 240 | L7: 0 | M7: 0 | N7: 0 | O7: 1 | P7: 1 | Q7: -200 | R7: 200 | S7: 0.8 | T7: 0.8 | U7: 200 | V7: 1875 | W7: 0.1 | X7: 0.9 | Y7: 0.5 | Z7: 9 | AA7: 原值保留；补值为算例假设，见字段说明
A8: PS_0007 | B8: 930632000000000000 | C8: 长龙山抽蓄 | D8: 1 | E8: 93043200000000 | F8: 400 | G8: -400 | H8: 0 | I8: 0 | J8: 480 | K8: 480 | L8: 0 | M8: 0 | N8: 0 | O8: 1 | P8: 1 | Q8: -400 | R8: 400 | S8: 0.8 | T8: 0.8 | U8: 400 | V8: 3750 | W8: 0.1 | X8: 0.9 | Y8: 0.5 | Z8: 9 | AA8: 原值保留；补值为算例假设，见字段说明
A9: PS_0008 | B9: 930632000000000000 | C9: 华溧抽_115.8机_JD | D9: 1 | E9: 93043200000000 | F9: 200 | G9: -200 | H9: 0 | I9: 0 | J9: 240 | K9: 240 | L9: 0 | M9: 0 | N9: 0 | O9: 1 | P9: 1 | Q9: -200 | R9: 200 | S9: 0.8 | T9: 0.8 | U9: 200 | V9: 1875 | W9: 0.1 | X9: 0.9 | Y9: 0.5 | Z9: 9 | AA9: 原值保留；补值为算例假设，见字段说明
A10: PS_0009 | B10: 930632000000000000 | C10: 华溧抽_215.8机_JD | D10: 1 | E10: 93043200000000 | F10: 200 | G10: -200 | H10: 0 | I10: 0 | J10: 240 | K10: 240 | L10: 0 | M10: 0 | N10: 0 | O10: 1 | P10: 1 | Q10: -200 | R10: 200 | S10: 0.8 | T10: 0.8 | U10: 200 | V10: 1875 | W10: 0.1 | X10: 0.9 | Y10: 0.5 | Z10: 9 | AA10: 原值保留；补值为算例假设，见字段说明
A11: PS_0010 | B11: 930632000000000000 | C11: 华溧抽_315.8机_JD | D11: 1 | E11: 93043200000000 | F11: 200 | G11: -200 | H11: 0 | I11: 0 | J11: 240 | K11: 240 | L11: 0 | M11: 0 | N11: 0 | O11: 1 | P11: 1 | Q11: -200 | R11: 200 | S11: 0.8 | T11: 0.8 | U11: 200 | V11: 1875 | W11: 0.1 | X11: 0.9 | Y11: 0.5 | Z11: 9 | AA11: 原值保留；补值为算例假设，见字段说明
A12: PS_0011 | B12: 930632000000000000 | C12: 华溧抽_415.8机_JD | D12: 1 | E12: 93043200000000 | F12: 200 | G12: -200 | H12: 0 | I12: 0 | J12: 240 | K12: 240 | L12: 0 | M12: 0 | N12: 0 | O12: 1 | P12: 1 | Q12: -200 | R12: 200 | S12: 0.8 | T12: 0.8 | U12: 200 | V12: 1875 | W12: 0.1 | X12: 0.9 | Y12: 0.5 | Z12: 9 | AA12: 原值保留；补值为算例假设，见字段说明
A13: PS_0012 | B13: 930632000000000000 | C13: 华溧抽_515.8机_JD | D13: 1 | E13: 93043200000000 | F13: 200 | G13: -200 | H13: 0 | I13: 0 | J13: 240 | K13: 240 | L13: 0 | M13: 0 | N13: 0 | O13: 1 | P13: 1 | Q13: -200 | R13: 200 | S13: 0.8 | T13: 0.8 | U13: 200 | V13: 1875 | W13: 0.1 | X13: 0.9 | Y13: 0.5 | Z13: 9 | AA13: 原值保留；补值为算例假设，见字段说明
... A26: PS_0025 | B26: 930632000000000000 | C26: 苏文抽G621.0机_JD | D26: 5 | E26: 93043200000000 | F26: 50 | G26: -50 | H26: 0 | I26: 0 | J26: 60 | K26: 60 | L26: 0 | M26: 0 | N26: 0 | O26: 1 | P26: 1 | Q26: -50 | R26: 50 | S26: 0.8 | T26: 0.8 | U26: 50 | V26: 468.75 | W26: 0.1 | X26: 0.9 | Y26: 0.5 | Z26: 9 | AA26: 原值保留；补值为算例假设，见字段说明

Sheet 核电
A1: UnitKey | B1: ID | C1: NAME | D1: SUBSTR(C.ID，12) | E1: PLANT_ID | F1: CAP | G1: MIN_POWER_GEN | H1: MIN_DOWN_TIME | I1: MIN_UP_TIME | J1: RAMP_LIMIT_UP | K1: RAMP_LIMIT_DOWN | L1: COST_A | M1: COST_B | N1: COST_C | O1: COST_START_UP | P1: COST_SHUT_DOWN | Q1: MIN_POWER_CHARGE | R1: MAX_POWER_CHARGE | S1: GEN_AFFI_FACTOR | T1: CHAEGE_AFFI_FACTOR | U1: INIT_POWER | V1: FOM_COST_PERIOD | W1: INIT_MAINTENANCE | X1: GEN_COST | Y1: DataStatus
A2: NUC_0001 | B2: 930632000000000000 | C2: 苏西陬G124.0机_JH | D2: 5 | E2: 93043200000000 | F2: 660 | G2: 660 | H2: 0 | I2: 0 | J2: 792 | K2: 792 | L2: 0 | M2: 0 | N2: 0 | O2: 100 | P2: 100 | Q2: 0 | R2: 660 | S2: 0 | T2: 0 | U2: 660 | V2: 30 | W2: 0 | X2: 0.01 | Y2: 原值保留；补值为算例假设，见字段说明
A3: NUC_0002 | B3: 930632000000000000 | C3: 苏西陬G224.0机_JH | D3: 5 | E3: 93043200000000 | F3: 660 | G3: 660 | H3: 0 | I3: 0 | J3: 792 | K3: 792 | L3: 0 | M3: 0 | N3: 0 | O3: 100 | P3: 100 | Q3: 0 | R3: 660 | S3: 0 | T3: 0 | U3: 660 | V3: 30 | W3: 0 | X3: 0.01 | Y3: 原值保留；补值为算例假设，见字段说明
A4: NUC_0003 | B4: 930632000000000000 | C4: 苏田湾_124.0机_JH | D4: 5 | E4: 93043200000000 | F4: 660 | G4: 660 | H4: 0 | I4: 0 | J4: 792 | K4: 792 | L4: 0 | M4: 0 | N4: 0 | O4: 100 | P4: 100 | Q4: 0 | R4: 660 | S4: 0 | T4: 0 | U4: 660 | V4: 30 | W4: 0 | X4: 0.01 | Y4: 原值保留；补值为算例假设，见字段说明
A5: NUC_0004 | B5: 930632000000000000 | C5: 苏田湾_224.0机_JH | D5: 5 | E5: 93043200000000 | F5: 660 | G5: 660 | H5: 0 | I5: 0 | J5: 792 | K5: 792 | L5: 0 | M5: 0 | N5: 0 | O5: 100 | P5: 100 | Q5: 0 | R5: 660 | S5: 0 | T5: 0 | U5: 660 | V5: 30 | W5: 0 | X5: 0.01 | Y5: 原值保留；补值为算例假设，见字段说明
A6: NUC_0005 | B6: 930632000000000000 | C6: 苏田湾_324.0机_JH | D6: 5 | E6: 93043200000000 | F6: 660 | G6: 660 | H6: 0 | I6: 0 | J6: 792 | K6: 792 | L6: 0 | M6: 0 | N6: 0 | O6: 100 | P6: 100 | Q6: 0 | R6: 660 | S6: 0 | T6: 0 | U6: 660 | V6: 30 | W6: 0 | X6: 0.01 | Y6: 原值保留；补值为算例假设，见字段说明
A7: NUC_0006 | B7: 930632000000000000 | C7: 苏田湾_424.0机_JH | D7: 5 | E7: 93043200000000 | F7: 660 | G7: 660 | H7: 0 | I7: 0 | J7: 792 | K7: 792 | L7: 0 | M7: 0 | N7: 0 | O7: 100 | P7: 100 | Q7: 0 | R7: 660 | S7: 0 | T7: 0 | U7: 660 | V7: 30 | W7: 0 | X7: 0.01 | Y7: 原值保留；补值为算例假设，见字段说明
A8: NUC_0007 | B8: 930632000000000000 | C8: 苏田三_524.0机_JH | D8: 5 | E8: 93043200000000 | F8: 660 | G8: 660 | H8: 0 | I8: 0 | J8: 792 | K8: 792 | L8: 0 | M8: 0 | N8: 0 | O8: 100 | P8: 100 | Q8: 0 | R8: 660 | S8: 0 | T8: 0 | U8: 660 | V8: 30 | W8: 0 | X8: 0.01 | Y8: 原值保留；补值为算例假设，见字段说明
A9: NUC_0008 | B9: 930632000000000000 | C9: 苏田三_624.0机_JH | D9: 5 | E9: 93043200000000 | F9: 660 | G9: 660 | H9: 0 | I9: 0 | J9: 792 | K9: 792 | L9: 0 | M9: 0 | N9: 0 | O9: 100 | P9: 100 | Q9: 0 | R9: 660 | S9: 0 | T9: 0 | U9: 660 | V9: 30 | W9: 0 | X9: 0.01 | Y9: 原值保留；补值为算例假设，见字段说明
A10: NUC_0009 | B10: 930632000000000000 | C10: 苏田三_724.0机_JH | D10: 5 | E10: 93043200000000 | F10: 660 | G10: 660 | H10: 0 | I10: 0 | J10: 792 | K10: 792 | L10: 0 | M10: 0 | N10: 0 | O10: 100 | P10: 100 | Q10: 0 | R10: 660 | S10: 0 | T10: 0 | U10: 660 | V10: 30 | W10: 0 | X10: 0.01 | Y10: 原值保留；补值为算例假设，见字段说明
A11: NUC_0010 | B11: 930632000000000000 | C11: 苏田三_824.0机_JH | D11: 5 | E11: 93043200000000 | F11: 660 | G11: 660 | H11: 0 | I11: 0 | J11: 792 | K11: 792 | L11: 0 | M11: 0 | N11: 0 | O11: 100 | P11: 100 | Q11: 0 | R11: 660 | S11: 0 | T11: 0 | U11: 660 | V11: 30 | W11: 0 | X11: 0.01 | Y11: 原值保留；补值为算例假设，见字段说明

Sheet 生物质
A1: UnitKey | B1: ID | C1: NAME | D1: SUBSTR(C.ID，12) | E1: PLANT_ID | F1: CAP | G1: MIN_POWER_GEN | H1: MIN_DOWN_TIME | I1: MIN_UP_TIME | J1: RAMP_LIMIT_UP | K1: RAMP_LIMIT_DOWN | L1: COST_A | M1: COST_B | N1: COST_C | O1: COST_START_UP | P1: COST_SHUT_DOWN | Q1: MIN_POWER_CHARGE | R1: MAX_POWER_CHARGE | S1: GEN_AFFI_FACTOR | T1: CHAEGE_AFFI_FACTOR | U1: INIT_POWER | V1: FOM_COST_PERIOD | W1: INIT_MAINTENANCE | X1: START_RAMP | Y1: STOP_RAMP | Z1: GEN_COST | AA1: DataStatus | AB1: ENERGY_LIMIT_MWH
A2: BIO_0001 | B2: 930632000000000000 | C2: 南京生物质 | D2: 1 | E2: 93043200000000 | F2: 165 | G2: 132 | H2: 72 | I2: 48 | J2: 198 | K2: 198 | L2: 8e-06 | M2: 0.012 | N2: 0.3 | O2: 3 | P2: 3 | Q2: 0 | R2: 165 | S2: 0 | T2: 0 | U2: 132 | V2: 21.25 | W2: 0 | X2: 165 | Y2: 165 | Z2: 0.04 | AA2: 原值保留；补值为算例假设，见字段说明 | AB2: 1320000
A3: BIO_0002 | B3: 930632000000000000 | C3: 镇江生物质 | D3: 1 | E3: 93043200000000 | F3: 91 | G3: 72.8 | H3: 72 | I3: 48 | J3: 109.2 | K3: 109.2 | L3: 8e-06 | M3: 0.012 | N3: 0.3 | O3: 3 | P3: 3 | Q3: 0 | R3: 91 | S3: 0 | T3: 0 | U3: 72.8 | V3: 21.25 | W3: 0 | X3: 91 | Y3: 91 | Z3: 0.04 | AA3: 原值保留；补值为算例假设，见字段说明 | AB3: 728000
A4: BIO_0003 | B4: 930632000000000000 | C4: 常州生物质 | D4: 1 | E4: 93043200000000 | F4: 76.6 | G4: 61.28 | H4: 72 | I4: 48 | J4: 91.92 | K4: 91.92 | L4: 8e-06 | M4: 0.012 | N4: 0.3 | O4: 3 | P4: 3 | Q4: 0 | R4: 76.6 | S4: 0 | T4: 0 | U4: 61.28 | V4: 21.25 | W4: 0 | X4: 76.6 | Y4: 76.6 | Z4: 0.04 | AA4: 原值保留；补值为算例假设，见字段说明 | AB4: 612800
A5: BIO_0004 | B5: 930632000000000000 | C5: 无锡生物质 | D5: 2 | E5: 93043200000000 | F5: 283 | G5: 226.4 | H5: 72 | I5: 48 | J5: 339.6 | K5: 339.6 | L5: 8e-06 | M5: 0.012 | N5: 0.3 | O5: 3 | P5: 3 | Q5: 0 | R5: 283 | S5: 0 | T5: 0 | U5: 226.4 | V5: 21.25 | W5: 0 | X5: 283 | Y5: 283 | Z5: 0.04 | AA5: 原值保留；补值为算例假设，见字段说明 | AB5: 2264000
A6: BIO_0005 | B6: 930632000000000000 | C6: 苏州生物质 | D6: 2 | E6: 93043200000000 | F6: 459.2 | G6: 367.36 | H6: 72 | I6: 48 | J6: 551.04 | K6: 551.04 | L6: 5e-06 | M6: 0.01 | N6: 0.5 | O6: 8 | P6: 8 | Q6: 0 | R6: 459.2 | S6: 0 | T6: 0 | U6: 367.36 | V6: 21.25 | W6: 0 | X6: 459.2 | Y6: 459.2 | Z6: 0.04 | AA6: 原值保留；补值为算例假设，见字段说明 | AB6: 3673600
A7: BIO_0006 | B7: 930632000000000000 | C7: 扬州生物质 | D7: 3 | E7: 93043200000000 | F7: 149 | G7: 119.2 | H7: 72 | I7: 48 | J7: 178.8 | K7: 178.8 | L7: 8e-06 | M7: 0.012 | N7: 0.3 | O7: 3 | P7: 3 | Q7: 0 | R7: 149 | S7: 0 | T7: 0 | U7: 119.2 | V7: 21.25 | W7: 0 | X7: 149 | Y7: 149 | Z7: 0.04 | AA7: 原值保留；补值为算例假设，见字段说明 | AB7: 1192000
A8: BIO_0007 | B8: 930632000000000000 | C8: 泰州生物质 | D8: 3 | E8: 93043200000000 | F8: 117.3 | G8: 93.84 | H8: 72 | I8: 48 | J8: 140.76 | K8: 140.76 | L8: 8e-06 | M8: 0.012 | N8: 0.3 | O8: 3 | P8: 3 | Q8: 0 | R8: 117.3 | S8: 0 | T8: 0 | U8: 93.84 | V8: 21.25 | W8: 0 | X8: 117.3 | Y8: 117.3 | Z8: 0.04 | AA8: 原值保留；补值为算例假设，见字段说明 | AB8: 938400
A9: BIO_0008 | B9: 930632000000000000 | C9: 徐州生物质 | D9: 4 | E9: 93043200000000 | F9: 329.2 | G9: 263.36 | H9: 72 | I9: 48 | J9: 395.04 | K9: 395.04 | L9: 5e-06 | M9: 0.01 | N9: 0.5 | O9: 8 | P9: 8 | Q9: 0 | R9: 329.2 | S9: 0 | T9: 0 | U9: 263.36 | V9: 21.25 | W9: 0 | X9: 329.2 | Y9: 329.2 | Z9: 0.04 | AA9: 原值保留；补值为算例假设，见字段说明 | AB9: 2633600
A10: BIO_0009 | B10: 930632000000000000 | C10: 宿迁生物质 | D10: 4 | E10: 93043200000000 | F10: 184.5 | G10: 147.6 | H10: 72 | I10: 48 | J10: 221.4 | K10: 221.4 | L10: 8e-06 | M10: 0.012 | N10: 0.3 | O10: 3 | P10: 3 | Q10: 0 | R10: 184.5 | S10: 0 | T10: 0 | U10: 147.6 | V10: 21.25 | W10: 0 | X10: 184.5 | Y10: 184.5 | Z10: 0.04 | AA10: 原值保留；补值为算例假设，见字段说明 | AB10: 1476000
A11: BIO_0010 | B11: 930632000000000000 | C11: 淮安生物质 | D11: 4 | E11: 93043200000000 | F11: 194.5 | G11: 155.6 | H11: 72 | I11: 48 | J11: 233.4 | K11: 233.4 | L11: 8e-06 | M11: 0.012 | N11: 0.3 | O11: 3 | P11: 3 | Q11: 0 | R11: 194.5 | S11: 0 | T11: 0 | U11: 155.6 | V11: 21.25 | W11: 0 | X11: 194.5 | Y11: 194.5 | Z11: 0.04 | AA11: 原值保留；补值为算例假设，见字段说明 | AB11: 1556000
A12: BIO_0011 | B12: 930632000000000000 | C12: 连云港生物质 | D12: 5 | E12: 93043200000000 | F12: 188 | G12: 150.4 | H12: 72 | I12: 48 | J12: 225.6 | K12: 225.6 | L12: 8e-06 | M12: 0.012 | N12: 0.3 | O12: 3 | P12: 3 | Q12: 0 | R12: 188 | S12: 0 | T12: 0 | U12: 150.4 | V12: 21.25 | W12: 0 | X12: 188 | Y12: 188 | Z12: 0.04 | AA12: 原值保留；补值为算例假设，见字段说明 | AB12: 1504000
A13: BIO_0012 | B13: 930632000000000000 | C13: 盐城生物质 | D13: 5 | E13: 93043200000000 | F13: 326.5 | G13: 261.2 | H13: 72 | I13: 48 | J13: 391.8 | K13: 391.8 | L13: 5e-06 | M13: 0.01 | N13: 0.5 | O13: 8 | P13: 8 | Q13: 0 | R13: 326.5 | S13: 0 | T13: 0 | U13: 261.2 | V13: 21.25 | W13: 0 | X13: 326.5 | Y13: 326.5 | Z13: 0.04 | AA13: 原值保留；补值为算例假设，见字段说明 | AB13: 2612000
A14: BIO_0013 | B14: 930632000000000000 | C14: 南通生物质 | D14: 5 | E14: 93043200000000 | F14: 228.5 | G14: 182.8 | H14: 72 | I14: 48 | J14: 274.2 | K14: 274.2 | L14: 8e-06 | M14: 0.012 | N14: 0.3 | O14: 3 | P14: 3 | Q14: 0 | R14: 228.5 | S14: 0 | T14: 0 | U14: 182.8 | V14: 21.25 | W14: 0 | X14: 228.5 | Y14: 228.5 | Z14: 0.04 | AA14: 原值保留；补值为算例假设，见字段说明 | AB14: 1828000

Sheet 其他规划
A1: UnitKey | B1: ID | C1: NAME | D1: SUBSTR(C.ID，12) | E1: PLANT_ID | F1: CAP | G1: MIN_POWER_GEN | H1: MIN_DOWN_TIME | I1: MIN_UP_TIME | J1: RAMP_LIMIT_UP | K1: RAMP_LIMIT_DOWN | L1: COST_A | M1: COST_B | N1: COST_C | O1: COST_START_UP | P1: COST_SHUT_DOWN | Q1: MIN_POWER_CHARGE | R1: MAX_POWER_CHARGE | S1: GEN_AFFI_FACTOR | T1: CHAEGE_AFFI_FACTOR | U1: DataStatus
A2: PLAN_0001 | B2: 930632000000000000 | C2: 南京其他规划 | D2: 1 | E2: 93043200000000 | F2: 50 | G2: 40.3361 | H2: 72 | I2: 48 | J2: 60 | K2: 60 | L2: 8e-06 | M2: 0.012 | N2: 0.3 | O2: 3 | P2: 3 | Q2: 0 | R2: 50.4202 | S2: 0 | T2: 0 | U2: 原始规划资料，未纳入在役调度
A3: PLAN_0002 | B3: 930632000000000000 | C3: 镇江其他规划 | D3: 1 | E3: 93043200000000 | F3: 50 | G3: 40.3361 | H3: 72 | I3: 48 | J3: 60 | K3: 60 | L3: 8e-06 | M3: 0.012 | N3: 0.3 | O3: 3 | P3: 3 | Q3: 0 | R3: 50.4202 | S3: 0 | T3: 0 | U3: 原始规划资料，未纳入在役调度
A4: PLAN_0003 | B4: 930632000000000000 | C4: 常州其他规划 | D4: 1 | E4: 93043200000000 | F4: 50 | G4: 40.3361 | H4: 72 | I4: 48 | J4: 60 | K4: 60 | L4: 8e-06 | M4: 0.012 | N4: 0.3 | O4: 3 | P4: 3 | Q4: 0 | R4: 50.4202 | S4: 0 | T4: 0 | U4: 原始规划资料，未纳入在役调度
A5: PLAN_0004 | B5: 930632000000000000 | C5: 无锡其他规划 | D5: 2 | E5: 93043200000000 | F5: 50 | G5: 40.3361 | H5: 72 | I5: 48 | J5: 60 | K5: 60 | L5: 8e-06 | M5: 0.012 | N5: 0.3 | O5: 3 | P5: 3 | Q5: 0 | R5: 50.4202 | S5: 0 | T5: 0 | U5: 原始规划资料，未纳入在役调度
A6: PLAN_0005 | B6: 930632000000000000 | C6: 苏州其他规划 | D6: 2 | E6: 93043200000000 | F6: 100 | G6: 80.6722 | H6: 72 | I6: 48 | J6: 120 | K6: 120 | L6: 3e-06 | M6: 0.008 | N6: 0.8 | O6: 30 | P6: 30 | Q6: 0 | R6: 756.3025 | S6: 0 | T6: 0 | U6: 原始规划资料，未纳入在役调度
A7: PLAN_0006 | B7: 930632000000000000 | C7: 扬州其他规划 | D7: 3 | E7: 93043200000000 | F7: 50 | G7: 40.3361 | H7: 72 | I7: 48 | J7: 60 | K7: 60 | L7: 8e-06 | M7: 0.012 | N7: 0.3 | O7: 3 | P7: 3 | Q7: 0 | R7: 50.4202 | S7: 0 | T7: 0 | U7: 原始规划资料，未纳入在役调度
A8: PLAN_0007 | B8: 930632000000000000 | C8: 泰州其他规划 | D8: 3 | E8: 93043200000000 | F8: 50 | G8: 40.3361 | H8: 72 | I8: 48 | J8: 60 | K8: 60 | L8: 8e-06 | M8: 0.012 | N8: 0.3 | O8: 3 | P8: 3 | Q8: 0 | R8: 50.4202 | S8: 0 | T8: 0 | U8: 原始规划资料，未纳入在役调度
A9: PLAN_0008 | B9: 930632000000000000 | C9: 徐州其他规划 | D9: 4 | E9: 93043200000000 | F9: 50 | G9: 40.3361 | H9: 72 | I9: 48 | J9: 60 | K9: 60 | L9: 8e-06 | M9: 0.012 | N9: 0.3 | O9: 3 | P9: 3 | Q9: 0 | R9: 50.4202 | S9: 0 | T9: 0 | U9: 原始规划资料，未纳入在役调度
A10: PLAN_0009 | B10: 930632000000000000 | C10: 宿迁其他规划 | D10: 4 | E10: 93043200000000 | F10: 50 | G10: 40.3361 | H10: 72 | I10: 48 | J10: 60 | K10: 60 | L10: 8e-06 | M10: 0.012 | N10: 0.3 | O10: 3 | P10: 3 | Q10: 0 | R10: 50.4202 | S10: 0 | T10: 0 | U10: 原始规划资料，未纳入在役调度
A11: PLAN_0010 | B11: 930632000000000000 | C11: 淮安其他规划 | D11: 4 | E11: 93043200000000 | F11: 50 | G11: 40.3361 | H11: 72 | I11: 48 | J11: 60 | K11: 60 | L11: 8e-06 | M11: 0.012 | N11: 0.3 | O11: 3 | P11: 3 | Q11: 0 | R11: 50.4202 | S11: 0 | T11: 0 | U11: 原始规划资料，未纳入在役调度
A12: PLAN_0011 | B12: 930632000000000000 | C12: 连云港其他规划 | D12: 5 | E12: 93043200000000 | F12: 50 | G12: 40.3361 | H12: 72 | I12: 48 | J12: 60 | K12: 60 | L12: 8e-06 | M12: 0.012 | N12: 0.3 | O12: 3 | P12: 3 | Q12: 0 | R12: 50.4202 | S12: 0 | T12: 0 | U12: 原始规划资料，未纳入在役调度
A13: PLAN_0012 | B13: 930632000000000000 | C13: 盐城其他规划 | D13: 5 | E13: 93043200000000 | F13: 50 | G13: 40.3361 | H13: 72 | I13: 48 | J13: 60 | K13: 60 | L13: 8e-06 | M13: 0.012 | N13: 0.3 | O13: 3 | P13: 3 | Q13: 0 | R13: 50.4202 | S13: 0 | T13: 0 | U13: 原始规划资料，未纳入在役调度
A14: PLAN_0013 | B14: 930632000000000000 | C14: 南通其他规划 | D14: 5 | E14: 93043200000000 | F14: 50 | G14: 40.3361 | H14: 72 | I14: 48 | J14: 60 | K14: 60 | L14: 8e-06 | M14: 0.012 | N14: 0.3 | O14: 3 | P14: 3 | Q14: 0 | R14: 50.4202 | S14: 0 | T14: 0 | U14: 原始规划资料，未纳入在役调度

Sheet 风电
A1: UnitKey | B1: 分区编号 | C1: 分区名称 | D1: 装机容量_MW | E1: FOM_COST_PERIOD | F1: DataStatus
A2: W_0001 | B2: 1 | C2: 徐宿淮 | D2: 3808.15 | E2: 10 | F2: 原值保留；补值为算例假设，见字段说明
A3: W_0002 | B3: 2 | C3: 连盐通 | D3: 17655.73 | E3: 10 | F3: 原值保留；补值为算例假设，见字段说明
A4: W_0003 | B4: 3 | C4: 扬泰 | D4: 1473.07 | E4: 10 | F4: 原值保留；补值为算例假设，见字段说明
A5: W_0004 | B5: 4 | C5: 宁镇常 | D5: 100 | E5: 10 | F5: 原值保留；补值为算例假设，见字段说明
A6: W_0005 | B6: 5 | C6: 锡苏 | D6: 177.62 | E6: 10 | F6: 原值保留；补值为算例假设，见字段说明

Sheet 光伏
A1: UnitKey | B1: 分区编号 | C1: 分区名称 | D1: 装机容量_MW | E1: FOM_COST_PERIOD | F1: DataStatus
A2: PV_0001 | B2: 1 | C2: 徐宿淮 | D2: 15414.47 | E2: 3 | F2: 原值保留；补值为算例假设，见字段说明
A3: PV_0002 | B3: 2 | C3: 连盐通 | D3: 19291.9 | E3: 3 | F3: 原值保留；补值为算例假设，见字段说明
A4: PV_0003 | B4: 3 | C4: 扬泰 | D4: 7729.79 | E4: 3 | F4: 原值保留；补值为算例假设，见字段说明
A5: PV_0004 | B5: 4 | C5: 宁镇常 | D5: 8656.47 | E5: 3 | F5: 原值保留；补值为算例假设，见字段说明
A6: PV_0005 | B6: 5 | C6: 锡苏 | D6: 10554.52 | E6: 3 | F6: 原值保留；补值为算例假设，见字段说明

Sheet 电化学储能
A1: UnitKey | B1: NAME | C1: AreaID | D1: CAP | E1: ENERGY_MWH | F1: SOC_MIN | G1: SOC_MAX | H1: SOC_INITIAL | I1: ETA_CHARGE | J1: ETA_DISCHARGE | K1: SELF_DISCHARGE | L1: POWER_COST | M1: ENERGY_COST | N1: REPLACE_FACTOR | O1: MAX_CYCLES | P1: FOM_COST_PERIOD | Q1: FOM_ENERGY_PERIOD
A2: ES_ZJ_2018 | B2: 镇江一期储能（公开容量等值） | C2: 4 | D2: 101 | E2: 202 | F2: 0.1 | G2: 0.9 | H2: 0.5 | I2: 0.92195445 | J2: 0.92195445 | K2: 0.0001 | L2: 200000 | M2: 1100000 | N2: 0.8 | O2: 5000 | P2: 0.4 | Q2: 2.2

Sheet 径流式水电
A1: UnitKey | B1: NAME | C1: AreaID | D1: CAP | E1: GEN_COST | F1: FOM_COST_PERIOD

Sheet 库容式水电
A1: UnitKey | B1: NAME | C1: AreaID | D1: CAP | E1: GEN_COST | F1: FOM_COST_PERIOD

Sheet 光热
A1: UnitKey | B1: NAME | C1: AreaID | D1: CAP | E1: MIN_POWER_GEN | F1: SF_EFFICIENCY | G1: MIRROR_AREA | H1: SOLAR_MULTIPLE | I1: DNI_REFERENCE | J1: THERMAL_EFFICIENCY | K1: HEAT_ETA_IN | L1: HEAT_ETA_OUT | M1: HEAT_LOSS | N1: HEAT_CH_MAX | O1: HEAT_DIS_MAX | P1: HEAT_MIN | Q1: HEAT_MAX | R1: HEAT_INITIAL | S1: RAMP_LIMIT_UP | T1: RAMP_LIMIT_DOWN | U1: START_RAMP | V1: STOP_RAMP | W1: GEN_COST | X1: FOM_COST_PERIOD | Y1: INIT_STATUS | Z1: INIT_POWER

Sheet 新能源友好电站
A1: UnitKey | B1: NAME | C1: AreaID | D1: WIND_CAP | E1: PV_CAP | F1: ES_POWER | G1: ENERGY_MWH | H1: SOC_MIN | I1: SOC_MAX | J1: SOC_INITIAL | K1: ETA_CHARGE | L1: ETA_DISCHARGE | M1: FOM_COST_PERIOD | N1: SELF_DISCHARGE | O1: POWER_COST | P1: ENERGY_COST | Q1: REPLACE_FACTOR | R1: MAX_CYCLES | S1: FOM_ENERGY_PERIOD | T1: WIND_FOM_PERIOD | U1: PV_FOM_PERIOD

Sheet 检修计划
A1: Year | B1: Type | C1: UnitKey | D1: UnitName | E1: AreaID | F1: StartTime | G1: EndTime | H1: Enabled | I1: Note
A2: 2023 | B2: 煤电 | C2: TH_0001 | D2: 苏华金_127.0机_JM | E2: 1 | F2: 44963 | G2: 44977 | H2: 1 | I2: 示例安排，非实际检修计划
A3: 2023 | B3: 煤电 | C3: TH_0002 | D3: 苏华金_227.0机_JM | E3: 1 | F3: 45173 | G3: 45187 | H3: 1 | I3: 示例安排，非实际检修计划
A4: 2023 | B4: 气电 | C4: GAS_0001 | D4: 苏协鑫_410.5机_Jr | E4: 1 | F4: 44991 | G4: 44998 | H4: 1 | I4: 示例安排，非实际检修计划
A5: 2023 | B5: 气电 | C5: GAS_0002 | D5: 苏协鑫_313.8机_Jr | E5: 1 | F5: 45208 | G5: 45215 | H5: 1 | I5: 示例安排，非实际检修计划
A6: 2023 | B6: 核电 | C6: NUC_0001 | D6: 苏西陬G124.0机_JH | E6: 5 | F6: 45054 | G6: 45075 | H6: 1 | I6: 示例安排，非实际检修计划
A7: 2023 | B7: 核电 | C7: NUC_0002 | D7: 苏西陬G224.0机_JH | E7: 5 | F7: 45201 | G7: 45222 | H7: 1 | I7: 示例安排，非实际检修计划
A8: 2023 | B8: 生物质 | C8: BIO_0001 | D8: 南京生物质 | E8: 1 | F8: 45005 | G8: 45012 | H8: 1 | I8: 示例安排，非实际检修计划
A9: 2023 | B9: 生物质 | C9: BIO_0002 | D9: 镇江生物质 | E9: 1 | F9: 45264 | G9: 45271 | H9: 1 | I9: 示例安排，非实际检修计划
A10: 2023 | B10: 抽水蓄能 | C10: PS_0001 | D10: 苏句抽G115.8机_JD | E10: 1 | F10: 45019 | G10: 45029 | H10: 1 | I10: 示例安排，非实际检修计划
A11: 2023 | B11: 抽水蓄能 | C11: PS_0002 | D11: 苏句抽G215.8机_JD | E11: 1 | F11: 45236 | G11: 45246 | H11: 1 | I11: 示例安排，非实际检修计划

Sheet 年度检修日历
A1: Date | B1: 徐宿淮检修台数 | C1: 连盐通检修台数 | D1: 扬泰检修台数 | E1: 宁镇常检修台数 | F1: 锡苏检修台数
A2: 44927 | B2: =COUNTIFS(检修计划!$E$2:$E$992,"1",检修计划!$F$2:$F$992,"<"&$A2+1,检修计划!$G$2:$G$992,">"&$A2,检修计划!$H$2:$H$992,1) | C2: =COUNTIFS(检修计划!$E$2:$E$992,"2",检修计划!$F$2:$F$992,"<"&$A2+1,检修计划!$G$2:$G$992,">"&$A2,检修计划!$H$2:$H$992,1) | D2: =COUNTIFS(检修计划!$E$2:$E$992,"3",检修计划!$F$2:$F$992,"<"&$A2+1,检修计划!$G$2:$G$992,">"&$A2,检修计划!$H$2:$H$992,1) | E2: =COUNTIFS(检修计划!$E$2:$E$992,"4",检修计划!$F$2:$F$992,"<"&$A2+1,检修计划!$G$2:$G$992,">"&$A2,检修计划!$H$2:$H$992,1) | F2: =COUNTIFS(检修计划!$E$2:$E$992,"5",检修计划!$F$2:$F$992,"<"&$A2+1,检修计划!$G$2:$G$992,">"&$A2,检修计划!$H$2:$H$992,1)
A3: 44928 | B3: =COUNTIFS(检修计划!$E$2:$E$992,"1",检修计划!$F$2:$F$992,"<"&$A3+1,检修计划!$G$2:$G$992,">"&$A3,检修计划!$H$2:$H$992,1) | C3: =COUNTIFS(检修计划!$E$2:$E$992,"2",检修计划!$F$2:$F$992,"<"&$A3+1,检修计划!$G$2:$G$992,">"&$A3,检修计划!$H$2:$H$992,1) | D3: =COUNTIFS(检修计划!$E$2:$E$992,"3",检修计划!$F$2:$F$992,"<"&$A3+1,检修计划!$G$2:$G$992,">"&$A3,检修计划!$H$2:$H$992,1) | E3: =COUNTIFS(检修计划!$E$2:$E$992,"4",检修计划!$F$2:$F$992,"<"&$A3+1,检修计划!$G$2:$G$992,">"&$A3,检修计划!$H$2:$H$992,1) | F3: =COUNTIFS(检修计划!$E$2:$E$992,"5",检修计划!$F$2:$F$992,"<"&$A3+1,检修计划!$G$2:$G$992,">"&$A3,检修计划!$H$2:$H$992,1)
A4: 44929 | B4: =COUNTIFS(检修计划!$E$2:$E$992,"1",检修计划!$F$2:$F$992,"<"&$A4+1,检修计划!$G$2:$G$992,">"&$A4,检修计划!$H$2:$H$992,1) | C4: =COUNTIFS(检修计划!$E$2:$E$992,"2",检修计划!$F$2:$F$992,"<"&$A4+1,检修计划!$G$2:$G$992,">"&$A4,检修计划!$H$2:$H$992,1) | D4: =COUNTIFS(检修计划!$E$2:$E$992,"3",检修计划!$F$2:$F$992,"<"&$A4+1,检修计划!$G$2:$G$992,">"&$A4,检修计划!$H$2:$H$992,1) | E4: =COUNTIFS(检修计划!$E$2:$E$992,"4",检修计划!$F$2:$F$992,"<"&$A4+1,检修计划!$G$2:$G$992,">"&$A4,检修计划!$H$2:$H$992,1) | F4: =COUNTIFS(检修计划!$E$2:$E$992,"5",检修计划!$F$2:$F$992,"<"&$A4+1,检修计划!$G$2:$G$992,">"&$A4,检修计划!$H$2:$H$992,1)
A5: 44930 | B5: =COUNTIFS(检修计划!$E$2:$E$992,"1",检修计划!$F$2:$F$992,"<"&$A5+1,检修计划!$G$2:$G$992,">"&$A5,检修计划!$H$2:$H$992,1) | C5: =COUNTIFS(检修计划!$E$2:$E$992,"2",检修计划!$F$2:$F$992,"<"&$A5+1,检修计划!$G$2:$G$992,">"&$A5,检修计划!$H$2:$H$992,1) | D5: =COUNTIFS(检修计划!$E$2:$E$992,"3",检修计划!$F$2:$F$992,"<"&$A5+1,检修计划!$G$2:$G$992,">"&$A5,检修计划!$H$2:$H$992,1) | E5: =COUNTIFS(检修计划!$E$2:$E$992,"4",检修计划!$F$2:$F$992,"<"&$A5+1,检修计划!$G$2:$G$992,">"&$A5,检修计划!$H$2:$H$992,1) | F5: =COUNTIFS(检修计划!$E$2:$E$992,"5",检修计划!$F$2:$F$992,"<"&$A5+1,检修计划!$G$2:$G$992,">"&$A5,检修计划!$H$2:$H$992,1)
A6: 44931 | B6: =COUNTIFS(检修计划!$E$2:$E$992,"1",检修计划!$F$2:$F$992,"<"&$A6+1,检修计划!$G$2:$G$992,">"&$A6,检修计划!$H$2:$H$992,1) | C6: =COUNTIFS(检修计划!$E$2:$E$992,"2",检修计划!$F$2:$F$992,"<"&$A6+1,检修计划!$G$2:$G$992,">"&$A6,检修计划!$H$2:$H$992,1) | D6: =COUNTIFS(检修计划!$E$2:$E$992,"3",检修计划!$F$2:$F$992,"<"&$A6+1,检修计划!$G$2:$G$992,">"&$A6,检修计划!$H$2:$H$992,1) | E6: =COUNTIFS(检修计划!$E$2:$E$992,"4",检修计划!$F$2:$F$992,"<"&$A6+1,检修计划!$G$2:$G$992,">"&$A6,检修计划!$H$2:$H$992,1) | F6: =COUNTIFS(检修计划!$E$2:$E$992,"5",检修计划!$F$2:$F$992,"<"&$A6+1,检修计划!$G$2:$G$992,">"&$A6,检修计划!$H$2:$H$992,1)
A7: 44932 | B7: =COUNTIFS(检修计划!$E$2:$E$992,"1",检修计划!$F$2:$F$992,"<"&$A7+1,检修计划!$G$2:$G$992,">"&$A7,检修计划!$H$2:$H$992,1) | C7: =COUNTIFS(检修计划!$E$2:$E$992,"2",检修计划!$F$2:$F$992,"<"&$A7+1,检修计划!$G$2:$G$992,">"&$A7,检修计划!$H$2:$H$992,1) | D7: =COUNTIFS(检修计划!$E$2:$E$992,"3",检修计划!$F$2:$F$992,"<"&$A7+1,检修计划!$G$2:$G$992,">"&$A7,检修计划!$H$2:$H$992,1) | E7: =COUNTIFS(检修计划!$E$2:$E$992,"4",检修计划!$F$2:$F$992,"<"&$A7+1,检修计划!$G$2:$G$992,">"&$A7,检修计划!$H$2:$H$992,1) | F7: =COUNTIFS(检修计划!$E$2:$E$992,"5",检修计划!$F$2:$F$992,"<"&$A7+1,检修计划!$G$2:$G$992,">"&$A7,检修计划!$H$2:$H$992,1)
A8: 44933 | B8: =COUNTIFS(检修计划!$E$2:$E$992,"1",检修计划!$F$2:$F$992,"<"&$A8+1,检修计划!$G$2:$G$992,">"&$A8,检修计划!$H$2:$H$992,1) | C8: =COUNTIFS(检修计划!$E$2:$E$992,"2",检修计划!$F$2:$F$992,"<"&$A8+1,检修计划!$G$2:$G$992,">"&$A8,检修计划!$H$2:$H$992,1) | D8: =COUNTIFS(检修计划!$E$2:$E$992,"3",检修计划!$F$2:$F$992,"<"&$A8+1,检修计划!$G$2:$G$992,">"&$A8,检修计划!$H$2:$H$992,1) | E8: =COUNTIFS(检修计划!$E$2:$E$992,"4",检修计划!$F$2:$F$992,"<"&$A8+1,检修计划!$G$2:$G$992,">"&$A8,检修计划!$H$2:$H$992,1) | F8: =COUNTIFS(检修计划!$E$2:$E$992,"5",检修计划!$F$2:$F$992,"<"&$A8+1,检修计划!$G$2:$G$992,">"&$A8,检修计划!$H$2:$H$992,1)
A9: 44934 | B9: =COUNTIFS(检修计划!$E$2:$E$992,"1",检修计划!$F$2:$F$992,"<"&$A9+1,检修计划!$G$2:$G$992,">"&$A9,检修计划!$H$2:$H$992,1) | C9: =COUNTIFS(检修计划!$E$2:$E$992,"2",检修计划!$F$2:$F$992,"<"&$A9+1,检修计划!$G$2:$G$992,">"&$A9,检修计划!$H$2:$H$992,1) | D9: =COUNTIFS(检修计划!$E$2:$E$992,"3",检修计划!$F$2:$F$992,"<"&$A9+1,检修计划!$G$2:$G$992,">"&$A9,检修计划!$H$2:$H$992,1) | E9: =COUNTIFS(检修计划!$E$2:$E$992,"4",检修计划!$F$2:$F$992,"<"&$A9+1,检修计划!$G$2:$G$992,">"&$A9,检修计划!$H$2:$H$992,1) | F9: =COUNTIFS(检修计划!$E$2:$E$992,"5",检修计划!$F$2:$F$992,"<"&$A9+1,检修计划!$G$2:$G$992,">"&$A9,检修计划!$H$2:$H$992,1)
A10: 44935 | B10: =COUNTIFS(检修计划!$E$2:$E$992,"1",检修计划!$F$2:$F$992,"<"&$A10+1,检修计划!$G$2:$G$992,">"&$A10,检修计划!$H$2:$H$992,1) | C10: =COUNTIFS(检修计划!$E$2:$E$992,"2",检修计划!$F$2:$F$992,"<"&$A10+1,检修计划!$G$2:$G$992,">"&$A10,检修计划!$H$2:$H$992,1) | D10: =COUNTIFS(检修计划!$E$2:$E$992,"3",检修计划!$F$2:$F$992,"<"&$A10+1,检修计划!$G$2:$G$992,">"&$A10,检修计划!$H$2:$H$992,1) | E10: =COUNTIFS(检修计划!$E$2:$E$992,"4",检修计划!$F$2:$F$992,"<"&$A10+1,检修计划!$G$2:$G$992,">"&$A10,检修计划!$H$2:$H$992,1) | F10: =COUNTIFS(检修计划!$E$2:$E$992,"5",检修计划!$F$2:$F$992,"<"&$A10+1,检修计划!$G$2:$G$992,">"&$A10,检修计划!$H$2:$H$992,1)
A11: 44936 | B11: =COUNTIFS(检修计划!$E$2:$E$992,"1",检修计划!$F$2:$F$992,"<"&$A11+1,检修计划!$G$2:$G$992,">"&$A11,检修计划!$H$2:$H$992,1) | C11: =COUNTIFS(检修计划!$E$2:$E$992,"2",检修计划!$F$2:$F$992,"<"&$A11+1,检修计划!$G$2:$G$992,">"&$A11,检修计划!$H$2:$H$992,1) | D11: =COUNTIFS(检修计划!$E$2:$E$992,"3",检修计划!$F$2:$F$992,"<"&$A11+1,检修计划!$G$2:$G$992,">"&$A11,检修计划!$H$2:$H$992,1) | E11: =COUNTIFS(检修计划!$E$2:$E$992,"4",检修计划!$F$2:$F$992,"<"&$A11+1,检修计划!$G$2:$G$992,">"&$A11,检修计划!$H$2:$H$992,1) | F11: =COUNTIFS(检修计划!$E$2:$E$992,"5",检修计划!$F$2:$F$992,"<"&$A11+1,检修计划!$G$2:$G$992,">"&$A11,检修计划!$H$2:$H$992,1)
A12: 44937 | B12: =COUNTIFS(检修计划!$E$2:$E$992,"1",检修计划!$F$2:$F$992,"<"&$A12+1,检修计划!$G$2:$G$992,">"&$A12,检修计划!$H$2:$H$992,1) | C12: =COUNTIFS(检修计划!$E$2:$E$992,"2",检修计划!$F$2:$F$992,"<"&$A12+1,检修计划!$G$2:$G$992,">"&$A12,检修计划!$H$2:$H$992,1) | D12: =COUNTIFS(检修计划!$E$2:$E$992,"3",检修计划!$F$2:$F$992,"<"&$A12+1,检修计划!$G$2:$G$992,">"&$A12,检修计划!$H$2:$H$992,1) | E12: =COUNTIFS(检修计划!$E$2:$E$992,"4",检修计划!$F$2:$F$992,"<"&$A12+1,检修计划!$G$2:$G$992,">"&$A12,检修计划!$H$2:$H$992,1) | F12: =COUNTIFS(检修计划!$E$2:$E$992,"5",检修计划!$F$2:$F$992,"<"&$A12+1,检修计划!$G$2:$G$992,">"&$A12,检修计划!$H$2:$H$992,1)
A13: 44938 | B13: =COUNTIFS(检修计划!$E$2:$E$992,"1",检修计划!$F$2:$F$992,"<"&$A13+1,检修计划!$G$2:$G$992,">"&$A13,检修计划!$H$2:$H$992,1) | C13: =COUNTIFS(检修计划!$E$2:$E$992,"2",检修计划!$F$2:$F$992,"<"&$A13+1,检修计划!$G$2:$G$992,">"&$A13,检修计划!$H$2:$H$992,1) | D13: =COUNTIFS(检修计划!$E$2:$E$992,"3",检修计划!$F$2:$F$992,"<"&$A13+1,检修计划!$G$2:$G$992,">"&$A13,检修计划!$H$2:$H$992,1) | E13: =COUNTIFS(检修计划!$E$2:$E$992,"4",检修计划!$F$2:$F$992,"<"&$A13+1,检修计划!$G$2:$G$992,">"&$A13,检修计划!$H$2:$H$992,1) | F13: =COUNTIFS(检修计划!$E$2:$E$992,"5",检修计划!$F$2:$F$992,"<"&$A13+1,检修计划!$G$2:$G$992,">"&$A13,检修计划!$H$2:$H$992,1)
... A366: 45291 | B366: =COUNTIFS(检修计划!$E$2:$E$992,"1",检修计划!$F$2:$F$992,"<"&$A366+1,检修计划!$G$2:$G$992,">"&$A366,检修计划!$H$2:$H$992,1) | C366: =COUNTIFS(检修计划!$E$2:$E$992,"2",检修计划!$F$2:$F$992,"<"&$A366+1,检修计划!$G$2:$G$992,">"&$A366,检修计划!$H$2:$H$992,1) | D366: =COUNTIFS(检修计划!$E$2:$E$992,"3",检修计划!$F$2:$F$992,"<"&$A366+1,检修计划!$G$2:$G$992,">"&$A366,检修计划!$H$2:$H$992,1) | E366: =COUNTIFS(检修计划!$E$2:$E$992,"4",检修计划!$F$2:$F$992,"<"&$A366+1,检修计划!$G$2:$G$992,">"&$A366,检修计划!$H$2:$H$992,1) | F366: =COUNTIFS(检修计划!$E$2:$E$992,"5",检修计划!$F$2:$F$992,"<"&$A366+1,检修计划!$G$2:$G$992,">"&$A366,检修计划!$H$2:$H$992,1)

Sheet 字段说明
A1: 设备类型 | B1: 字段名 | C1: 中文含义 | D1: 单位 | E1: 填写说明 | F1: 数据来源 | G1: 本次取值与口径 | H1: 资料年份 | I1: 来源或依据
A2: 煤电 | B2: UnitKey | C2: 机组唯一编号 | D2: 文本 | E2: 创建后固定，不随排序改变；新增机组用新编号 | F2: 新增稳定编号 | G2: 原有内容保留
A3: 煤电 | B3: ID | C3: 原始数据库编号 | D3: 原值 | E3: 原Excel超长数字已可能失真，不用作关联键 | F3: 原表/说明 | G3: 原有内容保留
A4: 煤电 | B4: NAME | C4: 机组名称 | D4: 文本 | E4: 保留源表 | F4: 原表/说明 | G4: 原有内容保留
A5: 煤电 | B5: SUBSTR(C.ID，12) | C5: 分区编号 | D5: 编号 | E5: 与分区表对应 | F5: 原表/说明 | G5: 原有内容保留
A6: 煤电 | B6: PLANT_ID | C6: 原电厂编号 | D6: 原值 | E6: 保留源表 | F6: 原表/说明 | G6: 原有内容保留
A7: 煤电 | B7: CAP | C7: 额定容量 | D7: MW | E7: 源表 | F7: 原表/说明 | G7: 原有内容保留
A8: 煤电 | B8: MIN_POWER_GEN | C8: 最小技术出力 | D8: MW | E8: 抽蓄原字段为带符号值，不作为抽水下限 | F8: 原表/说明 | G8: 原有内容保留
A9: 煤电 | B9: MIN_DOWN_TIME | C9: 最小连续停机时间 | D9: h | E9: 源表 | F9: 原表/说明 | G9: 原有内容保留
A10: 煤电 | B10: MIN_UP_TIME | C10: 最小连续开机时间 | D10: h | E10: 源表，核实时间口径 | F10: 原表/说明 | G10: 原有内容保留
A11: 煤电 | B11: RAMP_LIMIT_UP | C11: 向上爬坡 | D11: MW/时段 | E11: 需确认原始时段长度 | F11: 原表/说明 | G11: 原有内容保留
A12: 煤电 | B12: RAMP_LIMIT_DOWN | C12: 向下爬坡 | D12: MW/时段 | E12: 需确认原始时段长度 | F12: 原表/说明 | G12: 原有内容保留
A13: 煤电 | B13: COST_A | C13: 燃料二次项 | D13: 原货币单位/(h·MW²) | E13: 需确认原货币单位 | F13: 原表/说明 | G13: 原有内容保留
... A21: 煤电 | B21: CHAEGE_AFFI_FACTOR | C21: 抽水效率 | D21: 0~1 | E21: 沿用源表拼写 | F21: 原表/说明 | G21: 原有内容保留
A22: 煤电 | B22: INIT_STATUS | C22: 周期前运行状态 | D22: 0/1 | E22: 待填；仅煤电气电经济启停使用 | F22: 公开资料与算例假设区分见右侧 | G22: 算例初态：煤电开机且出力为原最小出力；气电停机且出力0。已持续时间取原最小开/停机时间较大者；非2023实测。改变起点时可重设。 | H22: 假设
A23: 煤电 | B23: INIT_POWER | C23: 周期前功率 | D23: MW | E23: 待填，与初始状态一致 | F23: 公开资料与算例假设区分见右侧 | G23: 算例初态：煤电开机且出力为原最小出力；气电停机且出力0。已持续时间取原最小开/停机时间较大者；非2023实测。改变起点时可重设。 | H23: 假设
A24: 煤电 | B24: FOM_COST_PERIOD | C24: 本周期固定运维系数 | D24: 万元/MW·基准期 | E24: 输入对应fixedCostReferenceHours小时；MATLAB自动折算到T小时。 | F24: 公开资料与算例假设区分见右侧 | G24: 算例假设，年度万元/MW：煤8.4、气7.4、抽蓄9、核30、生物质21.25、风10、光3；旧代码投资基数×假设运维率，非企业披露值。2023基准8760h，MATLAB按T/8760折算。 | H24: 算例基准2023 | I24: 本目录 synergy_jiangsu_25_legacy.m；运维比例为假设
A25: 煤电 | B25: INIT_HOURS | C25: 初始状态已持续时长 | D25: h | E25: 待填，整数小时 | F25: 公开资料与算例假设区分见右侧 | G25: 算例初态：煤电开机且出力为原最小出力；气电停机且出力0。已持续时间取原最小开/停机时间较大者；非2023实测。改变起点时可重设。 | H25: 假设
A26: 煤电 | B26: START_RAMP | C26: 启动允许功率变化 | D26: MW/时段 | E26: 待填 | F26: 公开资料与算例假设区分见右侧 | G26: 算例假设MW/h：煤电启动取原最小出力，其余启动取额定；停机均取额定。原运行爬坡值保留。 | H26: 假设
A27: 煤电 | B27: STOP_RAMP | C27: 停机允许功率变化 | D27: MW/时段 | E27: 待填 | F27: 公开资料与算例假设区分见右侧 | G27: 算例假设MW/h：煤电启动取原最小出力，其余启动取额定；停机均取额定。原运行爬坡值保留。 | H27: 假设
A28: 煤电 | B28: SO2_FACTOR | C28: SO2排放因子 | D28: t/MWh | E28: 待填 | F28: 公开资料与算例假设区分见右侧 | G28: 算例排放强度：SO2=0.1、NOx=0.15、烟尘=0.015 g/kWh，乘0.001填t/MWh；非机组监测数据。 | H28: 假设
A29: 煤电 | B29: NOX_FACTOR | C29: NOx排放因子 | D29: t/MWh | E29: 待填 | F29: 公开资料与算例假设区分见右侧 | G29: 算例排放强度：SO2=0.1、NOx=0.15、烟尘=0.015 g/kWh，乘0.001填t/MWh；非机组监测数据。 | H29: 假设
A30: 煤电 | B30: DUST_FACTOR | C30: 烟尘排放因子 | D30: t/MWh | E30: 待填 | F30: 公开资料与算例假设区分见右侧 | G30: 算例排放强度：SO2=0.1、NOx=0.15、烟尘=0.015 g/kWh，乘0.001填t/MWh；非机组监测数据。 | H30: 假设
A31: 煤电 | B31: DataStatus | C31: 数据状态 | D31: 文本 | E31: 源表数据保留；新增参数待填 | F31: 原表/说明 | G31: 原有内容保留
A32: 气电 | B32: UnitKey | C32: 机组唯一编号 | D32: 文本 | E32: 创建后固定，不随排序改变；新增机组用新编号 | F32: 新增稳定编号 | G32: 原有内容保留
A33: 气电 | B33: ID | C33: 原始数据库编号 | D33: 原值 | E33: 原Excel超长数字已可能失真，不用作关联键 | F33: 原表/说明 | G33: 原有内容保留
A34: 气电 | B34: NAME | C34: 机组名称 | D34: 文本 | E34: 保留源表 | F34: 原表/说明 | G34: 原有内容保留
A35: 气电 | B35: SUBSTR(C.ID，12) | C35: 分区编号 | D35: 编号 | E35: 与分区表对应 | F35: 原表/说明 | G35: 原有内容保留
A36: 气电 | B36: PLANT_ID | C36: 原电厂编号 | D36: 原值 | E36: 保留源表 | F36: 原表/说明 | G36: 原有内容保留
A37: 气电 | B37: CAP | C37: 额定容量 | D37: MW | E37: 源表 | F37: 原表/说明 | G37: 原有内容保留
A38: 气电 | B38: MIN_POWER_GEN | C38: 最小技术出力 | D38: MW | E38: 抽蓄原字段为带符号值，不作为抽水下限 | F38: 原表/说明 | G38: 原有内容保留
A39: 气电 | B39: MIN_DOWN_TIME | C39: 最小连续停机时间 | D39: h | E39: 源表 | F39: 原表/说明 | G39: 原有内容保留
A40: 气电 | B40: MIN_UP_TIME | C40: 最小连续开机时间 | D40: h | E40: 源表，核实时间口径 | F40: 原表/说明 | G40: 原有内容保留
A41: 气电 | B41: RAMP_LIMIT_UP | C41: 向上爬坡 | D41: MW/时段 | E41: 需确认原始时段长度 | F41: 原表/说明 | G41: 原有内容保留
A42: 气电 | B42: RAMP_LIMIT_DOWN | C42: 向下爬坡 | D42: MW/时段 | E42: 需确认原始时段长度 | F42: 原表/说明 | G42: 原有内容保留
... A51: 气电 | B51: CHAEGE_AFFI_FACTOR | C51: 抽水效率 | D51: 0~1 | E51: 沿用源表拼写 | F51: 原表/说明 | G51: 原有内容保留
A52: 气电 | B52: INIT_STATUS | C52: 周期前运行状态 | D52: 0/1 | E52: 待填；仅煤电气电经济启停使用 | F52: 公开资料与算例假设区分见右侧 | G52: 算例初态：煤电开机且出力为原最小出力；气电停机且出力0。已持续时间取原最小开/停机时间较大者；非2023实测。改变起点时可重设。 | H52: 假设
A53: 气电 | B53: INIT_POWER | C53: 周期前功率 | D53: MW | E53: 待填，与初始状态一致 | F53: 公开资料与算例假设区分见右侧 | G53: 算例初态：煤电开机且出力为原最小出力；气电停机且出力0。已持续时间取原最小开/停机时间较大者；非2023实测。改变起点时可重设。 | H53: 假设
A54: 气电 | B54: FOM_COST_PERIOD | C54: 本周期固定运维系数 | D54: 万元/MW·基准期 | E54: 输入对应fixedCostReferenceHours小时；MATLAB自动折算到T小时。 | F54: 公开资料与算例假设区分见右侧 | G54: 算例假设，年度万元/MW：煤8.4、气7.4、抽蓄9、核30、生物质21.25、风10、光3；旧代码投资基数×假设运维率，非企业披露值。2023基准8760h，MATLAB按T/8760折算。 | H54: 算例基准2023 | I54: 本目录 synergy_jiangsu_25_legacy.m；运维比例为假设
A55: 气电 | B55: START_RAMP | C55: 启动允许功率变化 | D55: MW/时段 | E55: 待填 | F55: 公开资料与算例假设区分见右侧 | G55: 算例假设MW/h：煤电启动取原最小出力，其余启动取额定；停机均取额定。原运行爬坡值保留。 | H55: 假设
...

Sheet 使用说明
A1: 事项 | B1: 说明
A2: 用途 | B2: 机组明细与技术、成本参数集中于本表；原分类表保持不变。
A3: 来源 | B3: 原始分区机组信息表_分类.xlsx；新增字段依据全部模型汇总-0916最新版.pdf。
A4: 颜色 | B4: 深蓝表头；浅黄色为新增待填参数。空白不是0。
A5: 关联编号 | B5: UnitKey为固定机组键，检修按此键关联；排序时不修改编号。
A6: 检修年份 | B6: 2023，与现有运行数据一致；只安排10台机组示例检修，不是实际计划。
A7: 检修区间 | B7: StartTime包含、EndTime不包含；日期为Excel真实日期，Enabled=1参与。
A8: 日历 | B8: 365天按分区统计当天发生检修的台数；支持检修计划前1000条记录。
A9: 尚缺设备 | B9: 空表表示本次没有该类设备；填写机组和参数后自动纳入模型。
A10: 货币口径 | B10: 成本原值保留；需在系统参数表填写costScaleToYuan。
A11: 固定运维 | B11: FOM输入对应fixedCostReferenceHours=8760小时，MATLAB自动乘T/8760及货币倍率10000。
A12: 超长原ID | B12: 原始数字精度不可恢复，以UnitKey为关联键。
... A17: 更新参数 | B17: 时序、节点按假设生成直接数值；改装机、效率、负荷曲线后须同步修改对应时序、节点。
